Workbook

Sheet 📊 Executive Dashboard
B1: OBSERVABILITY PLATFORM | TEST CLOSURE REPORT
B3: Release: v1.0 │ MVP-1 & MVP-2 │ Phases: ST · SIT │ Go / No-Go Decision
B4: Prepared by: QA Lead / Test Manager | I4: Date: [Enter Date] Version: 1.0
B7: ▶ GO / NO-GO VERDICT: [ GO ✔ ] | IT Testing Closure: COMPLETE | Status: READY FOR UAT COMMENCEMENT
B11: Total Test Cases | D11: Executed | F11: Passed | H11: Failed | J11: Blocked | L11: Pass %
B12: ='📋 ST Results'!C5+'📋 SIT Results'!C5 -> 624 | D12: ='📋 ST Results'!D5+'📋 SIT Results'!D5 -> 624 | F12: ='📋 ST Results'!E5+'📋 SIT Results'!E5 -> 602 | H12: ='📋 ST Results'!F5+'📋 SIT Results'!F5 -> 19 | J12: ='📋 ST Results'!G5+'📋 SIT Results'!G5 -> 3 | L12: =IFERROR(F12/B12*100,0) -> 96.474359
B16: PHASE-WISE TEST EXECUTION SUMMARY
B17: Phase | C17: MVP Scope | D17: Total TCs | E17: Executed | F17: Passed | G17: Failed | H17: Blocked | I17: Not Run | J17: Pass % | K17: Defects Raised | L17: Defects Closed | M17: Status
B18: System Testing (ST) | C18: MVP-1 & MVP-2 | D18: ='📋 ST Results'!C5 -> 443 | E18: ='📋 ST Results'!D5 -> 443 | F18: ='📋 ST Results'!E5 -> 427 | G18: ='📋 ST Results'!F5 -> 14 | H18: ='📋 ST Results'!G5 -> 2 | I18: ='📋 ST Results'!H5 -> 0 | J18: =IFERROR(E18/C18*100,0) -> 0 | K18: ='📋 ST Results'!K5 -> 16 | L18: ='📋 ST Results'!L5 -> 12 | M18: ='📋 ST Results'!M5 -> PASS
B19: System Integration Testing (SIT) | C19: MVP-1 & MVP-2 | D19: ='📋 SIT Results'!C5 -> 181 | E19: ='📋 SIT Results'!D5 -> 181 | F19: ='📋 SIT Results'!E5 -> 175 | G19: ='📋 SIT Results'!F5 -> 5 | H19: ='📋 SIT Results'!G5 -> 1 | I19: ='📋 SIT Results'!H5 -> 0 | J19: =IFERROR(E19/C19*100,0) -> 0 | K19: ='📋 SIT Results'!K5 -> 6 | L19: ='📋 SIT Results'!L5 -> 6 | M19: ='📋 SIT Results'!M5 -> PASS
B20: TOTAL / COMBINED | C20: Both MVPs | D20: =SUM(C18:C19) -> 0 | E20: =SUM(D18:D19) -> 624 | F20: =SUM(E18:E19) -> 624 | G20: =SUM(F18:F19) -> 602 | H20: =SUM(G18:G19) -> 19 | I20: =SUM(H18:H19) -> 3 | J20: =IFERROR(SUM(E18:E19)/SUM(C18:C19)*100,0) -> 0 | K20: =SUM(J18:J19) -> 0 | L20: =SUM(K18:K19) -> 22 | M20: —
B22: MVP READINESS STATUS
B23: MVP | C23: Modules Covered | D23: Test Coverage % | E23: Defects (P1/P2) | F23: Defects (P3/P4) | G23: Deferred Issues | H23: UAT Ready | I23: Recommendation
B24: MVP-1: Data Ingestion & Pipeline | C24: Collector, Parser, Storage, API Gateway | D24: =IFERROR('📋 ST Results'!P7,0) -> 95.238095 | E24: [Enter] | F24: [Enter] | G24: =COUNTA('🔴 Outstanding Issues'!B4:B20) -> 14 | H24: YES ✔ | I24: GO
B25: MVP-2: Dashboards & Alerting | C25: Visualization, Alert Engine, Notification, RBAC | D25: =IFERROR('📋 ST Results'!P14,0) -> 95.833333 | E25: [Enter] | F25: [Enter] | G25: =COUNTA('🔴 Outstanding Issues'!B21:B30) -> 0 | H25: YES ✔ | I25: GO
B27: QUALITY GATE CHECKLIST (All criteria must be MET for GO decision)
B28: # | C28: Quality Gate Criterion | D28: Threshold | E28: Actual | F28: Status | G28: Owner
B29: 1 | C29: Pass % ≥ 95% across ST + SIT | D29: ≥ 95% | E29: =IFERROR(SUM('📋 ST Results'!E5,'📋 SIT Results'!E5)/SUM('📋 ST Results'!C5,'📋 SIT Results'!C5)*100,0) -> 96.474359 | F29: MET ✔ | G29: QA Lead
B30: 2 | C30: Zero open P1 / Critical defects | D30: 0 open P1 | E30: =COUNTIFS('🐛 Defect Tracker'!F6:F200,"P1",'🐛 Defect Tracker'!H6:H200,"Open") -> 0 | F30: MET ✔ | G30: Dev Lead
B31: 3 | C31: Zero open P2 / Major defects | D31: 0 open P2 | E31: =COUNTIFS('🐛 Defect Tracker'!F6:F200,"P2",'🐛 Defect Tracker'!H6:H200,"Open") -> 0 | F31: MET ✔ | G31: Dev Lead
B32: 4 | C32: Test execution ≥ 98% of planned TCs | D32: ≥ 98% | E32: =IFERROR(SUM('📋 ST Results'!D5,'📋 SIT Results'!D5)/SUM('📋 ST Results'!C5,'📋 SIT Results'!C5)*100,0) -> 100 | F32: MET ✔ | G32: QA Lead
B33: 5 | C33: All ST exit criteria signed off | D33: Yes | E33: YES | F33: MET ✔ | G33: Test Manager
B34: 6 | C34: All SIT exit criteria signed off | D34: Yes | E34: YES | F34: MET ✔ | G34: Test Manager
B35: 7 | C35: Regression suite fully executed | D35: Yes | E35: YES | F35: MET ✔ | G35: Automation Lead
B36: 8 | C36: Performance benchmarks met | D36: Latency < 200ms | E36: YES | F36: MET ✔ | G36: Perf Engineer
B37: 9 | C37: Security scans – no High/Critical findings | D37: 0 High/Crit | E37: YES | F37: MET ✔ | G37: SecOps
B38: 10 | C38: All deferred issues have release assignment | D38: Yes | E38: YES | F38: MET ✔ | G38: PM

Sheet 📌 Entry & Exit Criteria
B1: ENTRY & EXIT CRITERIA — ST · SIT PHASES
B4: All criteria must be verified and signed-off before phase commencement / closure
B6: ST — ENTRY CRITERIA
B7: # | C7: Criteria ID | E7: Owner | F7: Date Verified | G7: Status
B8: 1 | C8: EC-ST-01 | D8: Test environment (Observability Platform) fully provisioned and stable | F8: QA Lead | G8: [Enter Date] | H8: MET ✔
B9: 2 | C9: EC-ST-02 | D9: All MVP-1 & MVP-2 code modules deployed to ST environment (build sign-off) | F9: Dev Lead | G9: [Enter Date] | H9: MET ✔
B10: 3 | C10: EC-ST-03 | D10: Test data sets prepared (log streams, metrics, trace data) | F10: QA Analyst | G10: [Enter Date] | H10: MET ✔
B11: 4 | C11: EC-ST-04 | D11: ST test cases reviewed, baselined and loaded in test management tool | F11: Test Lead | G11: [Enter Date] | H11: MET ✔
B12: 5 | C12: EC-ST-05 | D12: Unit test coverage ≥ 80% confirmed by Dev team | F12: Dev Lead | G12: [Enter Date] | H12: MET ✔
B13: 6 | C13: EC-ST-06 | D13: Known P1/P2 defects from unit testing resolved or waived | F13: Dev Lead | G13: [Enter Date] | H13: MET ✔
B14: 7 | C14: EC-ST-07 | D14: Test infrastructure: agent simulators, mock integrations configured | F14: DevOps | G14: [Enter Date] | H14: MET ✔
B15: 8 | C15: EC-ST-08 | D15: Smoke test (sanity suite) passed with ≥ 95% pass rate | F15: QA Lead | G15: [Enter Date] | H15: MET ✔
B17: ST — EXIT CRITERIA
B18: # | C18: Criteria ID | E18: Owner | F18: Date Verified | G18: Status
B19: 1 | C19: EX-ST-01 | D19: Test execution ≥ 98% of planned test cases executed | F19: QA Lead | G19: [Enter Date] | H19: MET ✔
B20: 2 | C20: EX-ST-02 | D20: Overall pass rate ≥ 95% | F20: QA Lead | G20: [Enter Date] | H20: MET ✔
B21: 3 | C21: EX-ST-03 | D21: Zero open P1 (Critical) defects | F21: Dev Lead | G21: [Enter Date] | H21: MET ✔
B22: 4 | C22: EX-ST-04 | D22: Zero open P2 (Major) defects | F22: Dev Lead | G22: [Enter Date] | H22: MET ✔
B23: 5 | C23: EX-ST-05 | D23: All test execution results documented in test management tool | F23: Test Lead | G23: [Enter Date] | H23: MET ✔
B24: 6 | C24: EX-ST-06 | D24: Defect triage complete; all defects triaged and assigned | F24: QA Lead | G24: [Enter Date] | H24: MET ✔
B25: 7 | C25: EX-ST-07 | D25: ST closure report approved by Test Manager | F25: Test Manager | G25: [Enter Date] | H25: MET ✔
B27: SIT — ENTRY CRITERIA
B28: # | C28: Criteria ID | E28: Owner | F28: Date Verified | G28: Status
B29: 1 | C29: EC-SIT-01 | D29: ST exit criteria met and ST closure report signed off | F29: Test Manager | G29: [Enter Date] | H29: MET ✔
B30: 2 | C30: EC-SIT-02 | D30: SIT environment provisioned; all MVP-1 & MVP-2 integrations configured | F30: DevOps | G30: [Enter Date] | H30: MET ✔
B31: 3 | C31: EC-SIT-03 | D31: End-to-end integration scenarios reviewed and baselined | F31: QA Lead | G31: [Enter Date] | H31: MET ✔
B32: 4 | C32: EC-SIT-04 | D32: External system stubs / real connections verified (Kafka, S3, PagerDuty, Slack) | F32: Arch Lead | G32: [Enter Date] | H32: MET ✔
B33: 5 | C33: EC-SIT-05 | D33: Data migration scripts (if any) verified in lower environment | F33: Dev Lead | G33: [Enter Date] | H33: MET ✔
B34: 6 | C34: EC-SIT-06 | D34: Performance baseline established from ST phase | F34: Perf Engineer | G34: [Enter Date] | H34: MET ✔
B35: 7 | C35: EC-SIT-07 | D35: Security scan tools configured on SIT environment | F35: SecOps | G35: [Enter Date] | H35: MET ✔
B37: SIT — EXIT CRITERIA
B38: # | C38: Criteria ID | E38: Owner | F38: Date Verified | G38: Status
B39: 1 | C39: EX-SIT-01 | D39: All end-to-end integration scenarios executed and passed | F39: QA Lead | G39: [Enter Date] | H39: MET ✔
B40: 2 | C40: EX-SIT-02 | D40: Cross-MVP data flow validated (ingestion → storage → visualization → alert) | F40: QA Lead | G40: [Enter Date] | H40: MET ✔
B41: 3 | C41: EX-SIT-03 | D41: Zero open P1/P2 defects | F41: Dev Lead | G41: [Enter Date] | H41: MET ✔
B42: 4 | C42: EX-SIT-04 | D42: Performance test: p95 latency ≤ 200ms; throughput ≥ target | F42: Perf Engineer | G42: [Enter Date] | H42: MET ✔
B43: 5 | C43: EX-SIT-05 | D43: Security scan complete; no High/Critical vulnerabilities open | F43: SecOps | G43: [Enter Date] | H43: MET ✔
B44: 6 | C44: EX-SIT-06 | D44: UAT environment seeded; UAT test data prepared | F44: QA Lead | G44: [Enter Date] | H44: MET ✔
B45: 7 | C45: EX-SIT-07 | D45: SIT closure report approved by stakeholders | F45: Test Manager | G45: [Enter Date] | H45: MET ✔
B46: 8 | C46: EX-SIT-08 | D46: Leadership sign-off obtained for UAT commencement | F46: Leadership | G46: [Enter Date] | H46: MET ✔

Sheet 📋 ST Results
B1: SYSTEM TESTING (ST) — MODULE-WISE RESULTS
B5: MODULE / COMPONENT | C5: =C20 -> 443 | D5: =D20 -> 443 | E5: =E20 -> 427 | F5: =F20 -> 14 | G5: =G20 -> 2 | H5: =H20 -> 0 | I5: Pass % | J5: Fail % | K5: =K20 -> 16 | L5: =L20 -> 12 | M5: PASS | O5: Coverage %
B6: MVP-1: Data Ingestion & Pipeline
B7: Log Collector Agent | C7: 42 | D7: 42 | E7: 40 | F7: 1 | G7: 1 | H7: 0 | I7: =IFERROR(D7/C7*100,0) -> 100 | J7: =IFERROR(E7/C7*100,0) -> 95.238095 | K7: 2 | L7: 2 | M7: WARN | O7: =IFERROR(C7/B7*100,0) -> 0 | P7: =IFERROR(E7/C7*100,0) -> 95.238095
B8: Metric Scraper Service | C8: 38 | D8: 38 | E8: 37 | F8: 1 | G8: 0 | H8: 0 | I8: =IFERROR(D8/C8*100,0) -> 100 | J8: =IFERROR(E8/C8*100,0) -> 97.368421 | K8: 1 | L8: 1 | M8: WARN | O8: =IFERROR(C8/B8*100,0) -> 0
B9: Trace Ingestion Pipeline | C9: 35 | D9: 35 | E9: 34 | F9: 1 | G9: 0 | H9: 0 | I9: =IFERROR(D9/C9*100,0) -> 100 | J9: =IFERROR(E9/C9*100,0) -> 97.142857 | K9: 1 | L9: 1 | M9: WARN | O9: =IFERROR(C9/B9*100,0) -> 0
B10: Data Parser & Normalizer | C10: 45 | D10: 45 | E10: 43 | F10: 2 | G10: 0 | H10: 0 | I10: =IFERROR(D10/C10*100,0) -> 100 | J10: =IFERROR(E10/C10*100,0) -> 95.555556 | K10: 2 | L10: 1 | M10: FAIL | O10: =IFERROR(C10/B10*100,0) -> 0
B11: Storage Layer (TimeSeries DB) | C11: 50 | D11: 50 | E11: 48 | F11: 2 | G11: 0 | H11: 0 | I11: =IFERROR(D11/C11*100,0) -> 100 | J11: =IFERROR(E11/C11*100,0) -> 96 | K11: 2 | L11: 1 | M11: FAIL | O11: =IFERROR(C11/B11*100,0) -> 0
B12: API Gateway / Query Service | C12: 40 | D12: 40 | E12: 39 | F12: 1 | G12: 0 | H12: 0 | I12: =IFERROR(D12/C12*100,0) -> 100 | J12: =IFERROR(E12/C12*100,0) -> 97.5 | K12: 1 | L12: 1 | M12: WARN | O12: =IFERROR(C12/B12*100,0) -> 0
B13: MVP-2: Dashboards & Alerting
B14: Dashboard Builder | C14: 48 | D14: 48 | E14: 46 | F14: 2 | G14: 0 | H14: 0 | I14: =IFERROR(D14/C14*100,0) -> 100 | J14: =IFERROR(E14/C14*100,0) -> 95.833333 | K14: 2 | L14: 1 | M14: FAIL | O14: =IFERROR(C14/B14*100,0) -> 0 | P14: =IFERROR(E14/C14*100,0) -> 95.833333
B15: Alert Rule Engine | C15: 52 | D15: 52 | E15: 50 | F15: 2 | G15: 0 | H15: 0 | I15: =IFERROR(D15/C15*100,0) -> 100 | J15: =IFERROR(E15/C15*100,0) -> 96.153846 | K15: 2 | L15: 1 | M15: FAIL | O15: =IFERROR(C15/B15*100,0) -> 0
B16: Notification Dispatcher | C16: 38 | D16: 38 | E16: 36 | F16: 1 | G16: 1 | H16: 0 | I16: =IFERROR(D16/C16*100,0) -> 100 | J16: =IFERROR(E16/C16*100,0) -> 94.736842 | K16: 2 | L16: 2 | M16: WARN | O16: =IFERROR(C16/B16*100,0) -> 0
B17: RBAC & Auth Module | C17: 30 | D17: 30 | E17: 30 | F17: 0 | G17: 0 | H17: 0 | I17: =IFERROR(D17/C17*100,0) -> 100 | J17: =IFERROR(E17/C17*100,0) -> 100 | K17: 0 | L17: 0 | M17: PASS | O17: =IFERROR(C17/B17*100,0) -> 0
B18: Platform Admin Console | C18: 25 | D18: 25 | E18: 24 | F18: 1 | G18: 0 | H18: 0 | I18: =IFERROR(D18/C18*100,0) -> 100 | J18: =IFERROR(E18/C18*100,0) -> 96 | K18: 1 | L18: 1 | M18: WARN | O18: =IFERROR(C18/B18*100,0) -> 0
B20: TOTAL | C20: =SUM(C7:C12,C14:C18) -> 443 | D20: =SUM(D7:D12,D14:D18) -> 443 | E20: =SUM(E7:E12,E14:E18) -> 427 | F20: =SUM(F7:F12,F14:F18) -> 14 | G20: =SUM(G7:G12,G14:G18) -> 2 | H20: =SUM(H7:H12,H14:H18) -> 0 | I20: =IFERROR(E20/C20*100,0) -> 96.388262 | J20: =IFERROR(F20/C20*100,0) -> 3.1602709 | K20: =SUM(K7:K12,K14:K18) -> 16 | L20: =SUM(L7:L12,L14:L18) -> 12 | M20: SUMMARY

Sheet 📋 SIT Results
B1: SYSTEM INTEGRATION TESTING (SIT) — INTEGRATION SCENARIO RESULTS
B5: INTEGRATION SCENARIO | C5: =C18 -> 181 | D5: =D18 -> 181 | E5: =E18 -> 175 | F5: =F18 -> 5 | G5: =G18 -> 1 | H5: =H18 -> 0 | I5: Pass % | J5: Fail % | K5: =K18 -> 6 | L5: =L18 -> 6 | M5: PASS | O5: Coverage %
B6: MVP-1 × MVP-2 End-to-End Integration Scenarios
B7: Log Ingestion → Storage → Query API | C7: 20 | D7: 20 | E7: 20 | F7: 0 | G7: 0 | H7: 0 | I7: =IFERROR(D7/C7*100,0) -> 100 | J7: =IFERROR(E7/C7*100,0) -> 100 | K7: 0 | L7: 0 | M7: PASS | O7: =IFERROR(C7/B7*100,0) -> 0
B8: Metric Collection → TimeSeries → Dashboard | C8: 18 | D8: 18 | E8: 17 | F8: 1 | G8: 0 | H8: 0 | I8: =IFERROR(D8/C8*100,0) -> 100 | J8: =IFERROR(E8/C8*100,0) -> 94.444444 | K8: 1 | L8: 1 | M8: WARN | O8: =IFERROR(C8/B8*100,0) -> 0
B9: Trace Pipeline → Visualization | C9: 15 | D9: 15 | E9: 15 | F9: 0 | G9: 0 | H9: 0 | I9: =IFERROR(D9/C9*100,0) -> 100 | J9: =IFERROR(E9/C9*100,0) -> 100 | K9: 0 | L9: 0 | M9: PASS | O9: =IFERROR(C9/B9*100,0) -> 0
B10: Alert Rule → Evaluation → Notification Dispatch | C10: 22 | D10: 22 | E10: 21 | F10: 1 | G10: 0 | H10: 0 | I10: =IFERROR(D10/C10*100,0) -> 100 | J10: =IFERROR(E10/C10*100,0) -> 95.454545 | K10: 1 | L10: 1 | M10: WARN | O10: =IFERROR(C10/B10*100,0) -> 0
B11: RBAC → Dashboard Access Control | C11: 16 | D11: 16 | E11: 16 | F11: 0 | G11: 0 | H11: 0 | I11: =IFERROR(D11/C11*100,0) -> 100 | J11: =IFERROR(E11/C11*100,0) -> 100 | K11: 0 | L11: 0 | M11: PASS | O11: =IFERROR(C11/B11*100,0) -> 0
B12: API Gateway → Multi-tenant Routing | C12: 18 | D12: 18 | E12: 17 | F12: 0 | G12: 1 | H12: 0 | I12: =IFERROR(D12/C12*100,0) -> 100 | J12: =IFERROR(E12/C12*100,0) -> 94.444444 | K12: 1 | L12: 1 | M12: WARN | O12: =IFERROR(C12/B12*100,0) -> 0
B13: Cross-MVP: Correlation Engine | C13: 20 | D13: 20 | E13: 19 | F13: 1 | G13: 0 | H13: 0 | I13: =IFERROR(D13/C13*100,0) -> 100 | J13: =IFERROR(E13/C13*100,0) -> 95 | K13: 1 | L13: 1 | M13: WARN | O13: =IFERROR(C13/B13*100,0) -> 0
B14: External Integrations (Kafka/S3/PagerDuty) | C14: 25 | D14: 25 | E14: 24 | F14: 1 | G14: 0 | H14: 0 | I14: =IFERROR(D14/C14*100,0) -> 100 | J14: =IFERROR(E14/C14*100,0) -> 96 | K14: 1 | L14: 1 | M14: WARN | O14: =IFERROR(C14/B14*100,0) -> 0
B15: Performance Under Load (1K agents) | C15: 12 | D15: 12 | E15: 12 | F15: 0 | G15: 0 | H15: 0 | I15: =IFERROR(D15/C15*100,0) -> 100 | J15: =IFERROR(E15/C15*100,0) -> 100 | K15: 0 | L15: 0 | M15: PASS | O15: =IFERROR(C15/B15*100,0) -> 0
B16: Failover & Recovery Scenarios | C16: 15 | D16: 15 | E16: 14 | F16: 1 | G16: 0 | H16: 0 | I16: =IFERROR(D16/C16*100,0) -> 100 | J16: =IFERROR(E16/C16*100,0) -> 93.333333 | K16: 1 | L16: 1 | M16: WARN | O16: =IFERROR(C16/B16*100,0) -> 0
B18: TOTAL | C18: =SUM(C7:C17) -> 181 | D18: =SUM(D7:D17) -> 181 | E18: =SUM(E7:E17) -> 175 | F18: =SUM(F7:F17) -> 5 | G18: =SUM(G7:G17) -> 1 | H18: =SUM(H7:H17) -> 0 | I18: =IFERROR(E18/C18*100,0) -> 96.685083 | J18: =IFERROR(F18/C18*100,0) -> 2.7624309 | K18: =SUM(K7:K17) -> 6 | L18: =SUM(L7:L17) -> 6 | M18: SUMMARY

Sheet 🐛 Defect Tracker
B1: DEFECT TRACKER — MODULE-LEVEL | ST · SIT PHASES
B5: Defect ID | C5: Phase | D5: Module / Component | E5: Scenario / TC ID | F5: Priority | G5: Severity | H5: Status | I5: Assigned To | J5: Description / Summary | K5: Root Cause | L5: Resolution | M5: Target Fix Release | N5: Found Date | O5: Closed Date | P5: Remarks | Q5: DEFECT SUMMARY
B6: DEF-001 | C6: ST | D6: Log Collector Agent | E6: TC-ST-015 | F6: P2 | G6: Major | H6: Closed | I6: Dev-A | J6: Memory leak under 10K log/sec sustained load | K6: Resource mgmt bug | L6: Fixed – GC tuning applied | M6: v1.0 | N6: [Date] | O6: [Date] | P6: Verified in regression | Q6: Metric | R6: Count
B7: DEF-002 | C7: ST | D7: Metric Scraper Service | E7: TC-ST-028 | F7: P2 | G7: Major | H7: Closed | I7: Dev-B | J7: Scrape interval drift when >500 targets | K7: Timer precision issue | L7: Fixed – scheduler refactored | M7: v1.0 | N7: [Date] | O7: [Date] | Q7: Total Defects Raised | R7: =COUNTA(B6:B19) -> 14
B8: DEF-003 | C8: ST | D8: Data Parser & Normalizer | E8: TC-ST-042 | F8: P3 | G8: Minor | H8: Closed | I8: Dev-C | J8: Malformed JSON log not producing error event | K8: Edge case handling | L8: Fixed – added schema validation | M8: v1.0 | N8: [Date] | O8: [Date] | Q8: P1 – Critical | R8: =COUNTIF(F6:F19,"P1") -> 0
B9: DEF-004 | C9: ST | D9: Storage Layer | E9: TC-ST-056 | F9: P2 | G9: Major | H9: Closed | I9: Dev-D | J9: Query latency spike at 95th percentile > 500ms | K9: Missing index on tenant_id + timestamp | L9: Fixed – composite index added | M9: v1.0 | N9: [Date] | O9: [Date] | Q9: P2 – Major | R9: =COUNTIF(F6:F19,"P2") -> 7
B10: DEF-005 | C10: ST | D10: API Gateway | E10: TC-ST-063 | F10: P3 | G10: Minor | H10: Closed | I10: Dev-A | J10: Rate limiting header not returned on 429 response | K10: Response builder bug | L10: Fixed | M10: v1.0 | N10: [Date] | O10: [Date] | Q10: P3 – Minor | R10: =COUNTIF(F6:F19,"P3") -> 7
B11: DEF-006 | C11: ST | D11: Dashboard Builder | E11: TC-ST-078 | F11: P2 | G11: Major | H11: Closed | I11: Dev-E | J11: Time range picker resets on panel refresh | K11: State management bug | L11: Fixed – Redux state refactored | M11: v1.0 | N11: [Date] | O11: [Date] | Q11: P4 – Cosmetic | R11: =COUNTIF(F6:F19,"P4") -> 0
B12: DEF-007 | C12: ST | D12: Alert Rule Engine | E12: TC-ST-091 | F12: P2 | G12: Major | H12: Closed | I12: Dev-F | J12: Duplicate alerts fired on alert rule re-evaluation | K12: De-duplication logic missing | L12: Fixed – added fingerprint hash | M12: v1.0 | N12: [Date] | O12: [Date] | Q12: Status: Closed | R12: =COUNTIF(H6:H19,"Closed") -> 11
B13: DEF-008 | C13: ST | D13: Notification Dispatcher | E13: TC-ST-102 | F13: P3 | G13: Minor | H13: Open | I13: Dev-G | J13: PagerDuty webhook retry not honoring backoff | K13: Retry logic issue | L13: Fix in progress | M13: v1.1 | N13: [Date] | O13: — | P13: Deferred to v1.1 | Q13: Status: Open | R13: =COUNTIF(H6:H19,"Open") -> 3
B14: DEF-009 | C14: ST | D14: Log Collector Agent | E14: TC-ST-018 | F14: P3 | G14: Minor | H14: Closed | I14: Dev-A | J14: Agent startup delay 8s vs expected 5s | K14: Dependency init order | L14: Fixed | M14: v1.0 | N14: [Date] | O14: [Date] | Q14: Status: In Progress | R14: =COUNTIF(H6:H19,"In Progress") -> 0
B15: DEF-010 | C15: SIT | D15: Alert → Notification | E15: TC-SIT-024 | F15: P2 | G15: Major | H15: Closed | I15: Dev-F | J15: Alert not dispatched to Slack on resolution event | K15: Event type filter bug | L15: Fixed | M15: v1.0 | N15: [Date] | O15: [Date] | Q15: Closure Rate % | R15: =IFERROR(R7/R6*100,0) -> 0
B16: DEF-011 | C16: SIT | D16: Metric → Dashboard | E16: TC-SIT-031 | F16: P3 | G16: Minor | H16: Closed | I16: Dev-E | J16: Dashboard not refreshing on metric data lag > 30s | K16: Polling interval config | L16: Fixed – reduced polling | M16: v1.0 | N16: [Date] | O16: [Date] | Q16: ST Phase Defects | R16: =COUNTIF(C6:C19,"ST") -> 9
B17: DEF-012 | C17: SIT | D17: API Gateway Routing | E17: TC-SIT-045 | F17: P3 | G17: Minor | H17: Open | I17: Dev-B | J17: Multi-tenant header missing in downstream trace context | K17: Propagation gap | L17: Scheduled for v1.1 | M17: v1.1 | N17: [Date] | O17: — | P17: Deferred to v1.1 | Q17: SIT Phase Defects | R17: =COUNTIF(C6:C19,"SIT") -> 5
B18: DEF-013 | C18: SIT | D18: Failover Recovery | E18: TC-SIT-058 | F18: P2 | G18: Major | H18: Closed | I18: Dev-D | J18: Write-ahead log replay fails after ungraceful shutdown | K18: WAL corruption scenario | L18: Fixed – WAL checksum validation | M18: v1.0 | N18: [Date] | O18: [Date]
B19: DEF-014 | C19: SIT | D19: Correlation Engine | E19: TC-SIT-061 | F19: P3 | G19: Minor | H19: Open | I19: Dev-C | J19: Trace-to-log correlation shows <5% false positives | K19: Heuristic tuning needed | L19: Planned for v1.1 | M19: v1.1 | N19: [Date] | O19: — | P19: Accepted risk – cosmetic

Sheet 🔴 Outstanding Issues
B1: OUTSTANDING ISSUES — DEFERRED TO UPCOMING RELEASES
B5: ⚠ Issues listed below are ACCEPTED RISKS / DEFERRED ITEMS. None block Go-Live. Each has an assigned target release and owner.
B6: Issue ID | C6: Phase | D6: Module / Area | E6: Defect Ref | F6: Priority | G6: Impact | H6: Category | I6: Description | J6: Workaround Available | K6: Risk Level | L6: Target Release | M6: Owner | N6: Accepted By
B7: OI-001 | C7: ST | D7: Notification Dispatcher | E7: DEF-008 | F7: P3 | G7: Low | H7: Enhancement | I7: PagerDuty webhook retry does not honour exponential backoff; manual retry works | J7: Yes – manual retry | K7: Low | L7: v1.1 | M7: Dev-G | N7: QA Lead
B8: OI-002 | C8: SIT | D8: API Gateway | E8: DEF-012 | F8: P3 | G8: Medium | H8: Technical Debt | I8: Multi-tenant trace context propagation header missing in downstream calls; affects distributed tracing completeness | J8: Partial – tracing still functional | K8: Medium | L8: v1.1 | M8: Dev-B | N8: Arch Lead
B9: OI-003 | C9: SIT | D9: Correlation Engine | E9: DEF-014 | F9: P3 | G9: Low | H9: Optimisation | I9: Trace-to-log correlation shows <5% false-positive rate; heuristic model needs tuning | J9: No workaround needed – cosmetic | K9: Low | L9: v1.1 | M9: Dev-C | N9: QA Lead
B10: OI-004 | C10: ST | D10: Dashboard Builder | E10: N/A | F10: P4 | G10: Low | H10: UX Enhancement | I10: Panel colour theme does not persist on browser refresh in Firefox | J10: Yes – refresh once | K10: Low | L10: v1.2 | M10: Dev-E | N10: PM
B11: OI-005 | C11: ST | D11: RBAC Module | E11: N/A | F11: P4 | G11: Low | H11: Enhancement | I11: Bulk user import via CSV limited to 500 rows; workaround is batch upload | J11: Yes – batch upload | K11: Low | L11: v1.2 | M11: Dev-A | N11: PM
B12: OI-006 | C12: SIT | D12: Alert Rule Engine | E12: N/A | F12: P3 | G12: Low | H12: Performance | I12: Alert evaluation latency at 98th percentile is 320ms vs target 200ms under extreme load (5K rules) | J12: Acceptable at current scale | K12: Medium | L12: v1.1 | M12: Dev-F | N12: Perf Engineer
B13: OI-007 | C13: ST | D13: Platform Admin Console | E13: N/A | F13: P4 | G13: Low | H13: Enhancement | I13: Audit log export limited to 90 days in UI; full export via API works correctly | J13: Yes – use API export | K13: Low | L13: v1.2 | M13: Dev-D | N13: QA Lead
B14: OI-008 | C14: SIT | D14: Metric Scraper | E14: N/A | F14: P3 | G14: Low | H14: Stability | I14: Occasional 503 returned from scrape endpoint when target list reloads; auto-recovers in <5s | J14: Auto-recovers | K14: Low | L14: v1.1 | M14: Dev-B | N14: QA Lead
B16: DEFERRED ISSUE PLAN — RELEASE ROADMAP
B17: Target Release | C17: Count of Issues | D17: P2 Count | E17: P3 Count | F17: P4 Count | G17: Estimated Effort (days) | H17: Owner
B18: v1.1 (Next Sprint) | C18: =COUNTIF(L7:L14,"v1.1") -> 5 | D18: =COUNTIFS(F7:F14,"P2",L7:L14,"v1.1") -> 0 | E18: =COUNTIFS(F7:F14,"P3",L7:L14,"v1.1") -> 5 | F18: =COUNTIFS(F7:F14,"P4",L7:L14,"v1.1") -> 0 | G18: 5-8 | H18: Dev Lead | I18: All Medium-risk items
B19: v1.2 (Next Cycle) | C19: =COUNTIF(L7:L14,"v1.2") -> 3 | D19: =COUNTIFS(F7:F14,"P2",L7:L14,"v1.2") -> 0 | E19: =COUNTIFS(F7:F14,"P3",L7:L14,"v1.2") -> 0 | F19: =COUNTIFS(F7:F14,"P4",L7:L14,"v1.2") -> 3 | G19: 3-4 | H19: Dev Lead | I19: Low-risk UX improvements

Sheet ✅ UAT Entry Criteria
B1: UAT ENTRY CRITERIA & ACCEPTANCE CRITERIA — PRE-UAT HANDOVER DOCUMENT
B4: This document confirms IT Testing Closure (ST + SIT) and defines the conditions under which UAT may commence. UAT is to be conducted by the Leadership Team.
B6: 📋 IT TESTING STATUS: ST ✔ CLOSED | SIT ✔ CLOSED | UAT ► PENDING COMMENCEMENT | Decision: GO FOR UAT
B8: SECTION 1 — UAT ENTRY CRITERIA (All must be MET before UAT commences)
B9: # | C9: Criteria ID | D9: Entry Criterion | F9: Owner | G9: Evidence / Artefact | H9: Target Date | I9: Actual Date | J9: Status
B10: 1 | C10: EC-UAT-01 | D10: ST Phase fully closed — pass rate ≥ 95%, zero open P1/P2 | F10: Testing | G10: Test Manager | H10: ST Closure Report (this workbook) | J10: [Date] | K10: [Date] | L10: MET ✔
B11: 2 | C11: EC-UAT-02 | D11: SIT Phase fully closed — all integration scenarios passed, zero open P1/P2 | F11: Testing | G11: Test Manager | H11: SIT Closure Report (this workbook) | J11: [Date] | K11: [Date] | L11: MET ✔
B12: 3 | C12: EC-UAT-03 | D12: UAT environment provisioned, stable, and accessible to leadership team | F12: Infrastructure | G12: DevOps | H12: UAT Env URL shared: [Enter URL] | J12: [Date] | K12: [Date] | L12: MET ✔
B13: 4 | C13: EC-UAT-04 | D13: UAT test data loaded — representative production-like scenarios for Observability Platform | F13: Test Data | G13: QA Lead | H13: Test data load confirmation | J13: [Date] | K13: [Date] | L13: MET ✔
B14: 5 | C14: EC-UAT-05 | D14: Leadership user accounts created with correct roles (Admin / Viewer) and SSO configured | F14: Access | G14: DevOps | H14: User provisioning email sent | J14: [Date] | K14: [Date] | L14: MET ✔
B15: 6 | C15: EC-UAT-06 | D15: UAT test cases available in Jira and shared with UAT participants (links in Section 3) | F15: Test Management | G15: Test Lead | H15: Jira UAT Epic: [Enter link] | J15: [Date] | K15: [Date] | L15: MET ✔
B16: 7 | C16: EC-UAT-07 | D16: UAT test execution guide / user manual distributed to all UAT participants | F16: Documentation | G16: Test Lead | H16: Doc link: [Enter URL] | J16: [Date] | K16: [Date] | L16: MET ✔
B17: 8 | C17: EC-UAT-08 | D17: Known issues / outstanding items brief (deferred to v1.1 / v1.2) shared with leadership | F17: Communication | G17: QA Lead | H17: Outstanding Issues sheet (this workbook) | J17: [Date] | K17: [Date] | L17: MET ✔
B18: 9 | C18: EC-UAT-09 | D18: Walkthrough / demo session conducted with leadership prior to UAT start | F18: Communication | G18: PM | H18: Meeting invite / recording link: [Enter] | J18: [Date] | K18: [Date] | L18: MET ✔
B19: 10 | C19: EC-UAT-10 | D19: Performance & security test reports shared — p95 latency ≤ 200ms, no High/Critical sec findings | F19: Quality | G19: Perf & SecOps | H19: Perf report + Security scan report | J19: [Date] | K19: [Date] | L19: MET ✔
B20: 11 | C20: EC-UAT-11 | D20: Rollback & contingency plan documented and shared with stakeholders | F20: Risk | G20: Arch Lead | H20: Runbook: [Enter URL] | J20: [Date] | K20: [Date] | L20: MET ✔
B21: 12 | C21: EC-UAT-12 | D21: UAT schedule (start date, end date, daily check-in slots) confirmed with leadership | F21: Planning | G21: PM | H21: Calendar invite sent | J21: [Date] | K21: [Date] | L21: MET ✔
... B23: 14 | C23: EC-UAT-14 | D23: Dedicated UAT support contact (QA Lead + Dev on-call) available during UAT window | F23: Support | G23: QA Lead | H23: Support channel: [Enter Slack/Teams] | J23: [Date] | K23: [Date] | L23: MET ✔
B25: SECTION 2 — UAT ACCEPTANCE CRITERIA (Conditions for UAT PASS & Go-Live Approval)
B26: # | C26: Criteria ID | D26: Acceptance Criterion | F26: Threshold / Target | G26: Measurement Method | H26: Priority | I26: Status
B27: 1 | C27: AC-UAT-01 | D27: All UAT test cases executed by leadership team | F27: Test Execution | G27: 100% of UAT TCs in Jira executed | I27: Jira UAT Test Case Execution Report | L27: Mandatory | M27: PENDING
B28: 2 | C28: AC-UAT-02 | D28: UAT pass rate meets minimum threshold | F28: Quality Gate | G28: ≥ 90% pass rate across all UAT test cases | I28: Jira execution summary dashboard | L28: Mandatory | M28: PENDING
B29: 3 | C29: AC-UAT-03 | D29: Zero Blocker / Critical defects raised during UAT remain open at closure | F29: Defect Quality | G29: 0 open Blocker / Critical UAT defects | I29: Jira UAT defect filter: Priority=Blocker+Critical, Status≠Closed | L29: Mandatory | M29: PENDING
B30: 4 | C30: AC-UAT-04 | D30: No more than 2 open Major (P2) defects — all must have fix commitment | F30: Defect Quality | G30: ≤ 2 open P2 defects with fix date | I30: Jira defect report + commitment register | L30: Mandatory | M30: PENDING
B31: 5 | C31: AC-UAT-05 | D31: MVP-1 core flows validated by leadership: log ingestion, metric collection, trace pipeline, query API | F31: Functional Coverage | G31: All MVP-1 happy-path scenarios signed off | I31: UAT sign-off checklist (Section 4) | L31: Mandatory | M31: PENDING
B32: 6 | C32: AC-UAT-06 | D32: MVP-2 core flows validated: dashboard creation, alert rule fire, notification delivery, RBAC | F32: Functional Coverage | G32: All MVP-2 happy-path scenarios signed off | I32: UAT sign-off checklist (Section 4) | L32: Mandatory | M32: PENDING
B33: 7 | C33: AC-UAT-07 | D33: End-to-end observability scenario validated: ingest → store → visualise → alert → notify | F33: E2E Validation | G33: Full chain validated in UAT environment | I33: E2E scenario TC in Jira: [Enter link] | L33: Mandatory | M33: PENDING
B34: 8 | C34: AC-UAT-08 | D34: Leadership team confirms the platform meets stated business requirements | F34: Business Acceptance | G34: Positive sign-off from ≥ 3 of 5 stakeholders | I34: Leadership sign-off (Section 4 of this sheet) | L34: Mandatory | M34: PENDING
B35: 9 | C35: AC-UAT-09 | D35: Platform usability acceptable — navigation, dashboard UX, alert configuration flow | F35: Usability | G35: No critical UX blockers raised | I35: UAT feedback form responses | L35: Desirable | M35: PENDING
B36: 10 | C36: AC-UAT-10 | D36: Performance acceptable in UAT — dashboards load < 3s, alerts fire < 30s | F36: Performance | G36: Observed in UAT environment during testing | I36: Leadership observation + perf validation TC | L36: Desirable | M36: PENDING
B37: 11 | C37: AC-UAT-11 | D37: Data accuracy confirmed — logs/metrics/traces displayed correctly in dashboards | F37: Data Integrity | G37: Zero data discrepancy defects at Blocker/Critical | I37: Data validation TCs in Jira: [Enter link] | L37: Mandatory | M37: PENDING
B38: 12 | C38: AC-UAT-12 | D38: Security: leadership can access only their authorised tenants / roles (RBAC validation) | F38: Security / RBAC | G38: Zero unauthorised access incidents during UAT | I38: RBAC test TCs in Jira: [Enter link] | L38: Mandatory | M38: PENDING
B40: SECTION 3 — UAT TEST CASE REGISTER (Jira Links — replace placeholders with actual Jira URLs)
B41: # | C41: Jira TC ID | D41: Test Case Title | E41: MVP | F41: Module / Feature | G41: Priority | H41: Test Type | I41: Jira Link | J41: Expected Outcome
B42: 1 | C42: UAT-TC-001 | D42: Log ingestion from simulated agent — verify logs appear in dashboard | F42: MVP-1 | G42: Log Collector | H42: High | I42: Functional | J42: [Paste Jira TC URL] | K42: Logs visible within 30s in log explorer
B43: 2 | C43: UAT-TC-002 | D43: Metric collection — verify CPU/Memory metrics on dashboard | F43: MVP-1 | G43: Metric Scraper | H43: High | I43: Functional | J43: [Paste Jira TC URL] | K43: Metrics charted correctly with correct labels
B44: 3 | C44: UAT-TC-003 | D44: Trace search — query distributed trace and view waterfall | F44: MVP-1 | G44: Trace Ingestion | H44: High | I44: Functional | J44: [Paste Jira TC URL] | K44: Trace timeline and spans rendered accurately
B45: 4 | C45: UAT-TC-004 | D45: Create a custom dashboard panel (time-series chart) | F45: MVP-2 | G45: Dashboard Builder | H45: High | I45: Functional | J45: [Paste Jira TC URL] | K45: Panel created, saved, and persists on reload
B46: 5 | C46: UAT-TC-005 | D46: Configure an alert rule (threshold-based) and validate it fires | F46: MVP-2 | G46: Alert Rule Engine | H46: Critical | I46: Functional | J46: [Paste Jira TC URL] | K46: Alert fires within 60s of threshold breach
B47: 6 | C47: UAT-TC-006 | D47: Validate Slack notification received on alert trigger | F47: MVP-2 | G47: Notification | H47: High | I47: Integration | J47: [Paste Jira TC URL] | K47: Slack message received with correct alert details
...

Sheet 📈 Visualizations
B1: TEST METRICS VISUALIZATIONS — ST · SIT | All Charts Auto-Update
B5: DATA SOURCE (Auto-linked from Results sheets)
B6: Phase/Module | C6: Total | D6: Executed | E6: Passed | F6: Failed | G6: Blocked | H6: Not Run | K6: Priority | L6: Total | M6: Closed | N6: Open | O6: In Progress
B7: ST – MVP-1 | C7: ='📋 ST Results'!C7 -> 42 | D7: ='📋 ST Results'!D7 -> 42 | E7: ='📋 ST Results'!E7 -> 40 | F7: ='📋 ST Results'!F7 -> 1 | G7: ='📋 ST Results'!G7 -> 1 | H7: ='📋 ST Results'!H7 -> 0 | K7: P1 – Critical | L7: ='🐛 Defect Tracker'!R8 -> 0 | M7: =COUNTIFS('🐛 Defect Tracker'!F6:F200,"P1",'🐛 Defect Tracker'!H6:H200,"Closed") -> 0 | N7: =COUNTIFS('🐛 Defect Tracker'!F6:F200,"P1",'🐛 Defect Tracker'!H6:H200,"Open") -> 0 | O7: 0
B8: ST – MVP-2 | C8: ='📋 ST Results'!C14 -> 48 | D8: ='📋 ST Results'!D14 -> 48 | E8: ='📋 ST Results'!E14 -> 46 | F8: ='📋 ST Results'!F14 -> 2 | G8: ='📋 ST Results'!G14 -> 0 | H8: ='📋 ST Results'!H14 -> 0 | K8: P2 – Major | L8: ='🐛 Defect Tracker'!R9 -> 7 | M8: =COUNTIFS('🐛 Defect Tracker'!F6:F200,"P2",'🐛 Defect Tracker'!H6:H200,"Closed") -> 7 | N8: =COUNTIFS('🐛 Defect Tracker'!F6:F200,"P2",'🐛 Defect Tracker'!H6:H200,"Open") -> 0 | O8: 0
B9: SIT – All | C9: ='📋 SIT Results'!C18 -> 181 | D9: ='📋 SIT Results'!D18 -> 181 | E9: ='📋 SIT Results'!E18 -> 175 | F9: ='📋 SIT Results'!F18 -> 5 | G9: ='📋 SIT Results'!G18 -> 1 | H9: ='📋 SIT Results'!H18 -> 0 | K9: P3 – Minor | L9: ='🐛 Defect Tracker'!R10 -> 7 | M9: =COUNTIFS('🐛 Defect Tracker'!F6:F200,"P3",'🐛 Defect Tracker'!H6:H200,"Closed") -> 4 | N9: =COUNTIFS('🐛 Defect Tracker'!F6:F200,"P3",'🐛 Defect Tracker'!H6:H200,"Open") -> 3 | O9: 0
K10: P4 – Cosmetic | L10: ='🐛 Defect Tracker'!R11 -> 0 | M10: =COUNTIFS('🐛 Defect Tracker'!F6:F200,"P4",'🐛 Defect Tracker'!H6:H200,"Closed") -> 0 | N10: =COUNTIFS('🐛 Defect Tracker'!F6:F200,"P4",'🐛 Defect Tracker'!H6:H200,"Open") -> 0 | O10: 0

Sheet 📝 Release Notes
B1: RELEASE NOTES v1.0 — OBSERVABILITY PLATFORM | MVP-1 & MVP-2
B6: RELEASE OVERVIEW
B7: Release Version | C7: v1.0
B8: Release Date | C8: [Enter Date]
B9: Release Type | C9: Major – New Platform Launch
B10: MVPs Included | C10: MVP-1: Data Ingestion & Pipeline | MVP-2: Dashboards & Alerting
B11: Test Phases Completed | C11: ST (System Testing) + SIT (System Integration Testing)
B12: Go / No-Go Decision | C12: GO ✔
B14: MVP-1 FEATURES DELIVERED
B15: F-01 | C15: Log Collector Agent – multi-source, multi-format
B16: F-02 | C16: Metric Scraper with Prometheus-compatible pull model
B17: F-03 | C17: Distributed Trace Ingestion (OpenTelemetry compatible)
B18: F-04 | C18: Data Parser & Normalizer with schema registry
B19: F-05 | C19: TimeSeries Storage Layer – multi-tenant partitioned
B20: F-06 | C20: Query API Gateway – REST + GraphQL endpoints
B22: MVP-2 FEATURES DELIVERED
B23: F-07 | C23: Dashboard Builder – drag-and-drop, multi-panel
B24: F-08 | C24: Alert Rule Engine – threshold, anomaly, composite rules
B25: F-09 | C25: Notification Dispatcher – Slack, PagerDuty, Email, Webhook
B26: F-10 | C26: RBAC Module – Admin / Editor / Viewer roles, SSO ready
B27: F-11 | C27: Platform Admin Console – tenant mgmt, audit logs, config
B29: KNOWN LIMITATIONS (v1.0)
B30: L-01 | C30: PagerDuty webhook retry without exponential backoff → Fixed in v1.1
B31: L-02 | C31: Multi-tenant trace context propagation gap → Fixed in v1.1
B32: L-03 | C32: Trace-log correlation <5% false positives → Optimised in v1.1
B33: L-04 | C33: Dashboard theme not persisting in Firefox → Fixed in v1.2
B34: L-05 | C34: Bulk user CSV import limit 500 rows → Extended in v1.2
